Workbook

Sheet Debtors List
A2: Sr No | B2: Date of Sale | C2: Name of the Buyer | D2: Weight | E2: Rate | F2: Amount | G2: Palai | H2: Total Amount | I2: Advance | J2: Balance
A3: 1 | B3: 46125 | C3: Guddu Bhai | D3: 83 | E3: 600 | F3: 49800 | G3: 4000 | H3: 53800 | I3: 0 | J3: =+H3-I3 -> 53800
A4: 2 | B4: 46126 | C4: Azam Kharghar | D4: 136 | E4: 600 | F4: 81600 | G4: 4000 | H4: 89600 | J4: =+H4-I4 -> 89600
A5: 3 | B5: 46126 | C5: Azam Kharghar | G5: 4000
A6: 4 | B6: 46130 | C6: Salman Vikhroli | D6: 132 | E6: 600 | F6: 79200 | G6: 3000 | H6: 85200 | I6: 0 | J6: =+H6-I6 -> 85200
A7: 5 | B7: 46130 | C7: Salman Vikhroli | G7: 3000 | J7: =+H7-I7 -> 0
A8: 6 | B8: 46130 | C8: Iqbal Bhai Khar | D8: 358 | E8: 600 | F8: 214800 | G8: 3000 | H8: 229800 | I8: 0 | J8: =+H8-I8 -> 229800
A9: 7 | B9: 46130 | C9: Iqbal Bhai Khar | G9: 3000
A10: 8 | B10: 46130 | C10: Iqbal Bhai Khar | G10: 3000
A11: 9 | B11: 46130 | C11: Iqbal Bhai Khar | G11: 3000
A12: 10 | B12: 46130 | C12: Iqbal Bhai Khar | G12: 3000
A13: 11 | B13: 46130 | C13: Sajid Bhai Jogeshwari | D13: 144 | E13: 600 | F13: 86400 | G13: 3300 | H13: 93000 | I13: 0 | J13: =+H13-I13 -> 93000
A14: 12 | B14: 46130 | C14: Sajid Bhai Jogeshwari | G14: 3300
A15: 13 | B15: 46130 | C15: Kashaf Bhai c/o Sarfaraz bhai | D15: 128 | E15: 600 | F15: 76800 | G15: 3300 | H15: 83400 | I15: 0 | J15: =+H15-I15 -> 83400
A16: 14 | B16: 46130 | C16: Kashaf Bhai c/o Sarfaraz bhai | G16: 3300
A17: 15 | B17: 46131 | C17: Mohd Faizaan | D17: 123 | E17: 626.017 | F17: 77000.091 | G17: 3500 | H17: 84000.091 | J17: =+H17-I17 -> 84000.091
A18: 16 | B18: 46131 | C18: Mohd Faizaan | F18: 0 | G18: 3500
A19: 17 | B19: 46131 | C19: Salman Akhlak | D19: 115 | E19: 600 | F19: 69000 | G19: 3000 | H19: 75000 | I19: 70000 | J19: =+H19-I19 -> 5000
A20: 18 | B20: 46131 | C20: Salman Akhlak | G20: 3000
A21: 19 | B21: 46131 | C21: Shahid Shaikh Kurla | D21: 136 | E21: 600 | F21: 81600 | G21: 3400 | H21: 88400 | I21: 40000 | J21: =+H21-I21 -> 48400
A22: 20 | B22: 46131 | C22: Shahid Shaikh Kurla | G22: 3400
A23: 21 | B23: 46131 | C23: Shahid Shaikh Kurla | D23: 63 | E23: 700 | F23: 44100 | G23: 3400 | H23: 47500 | I23: 0 | J23: =+H23-I23 -> 47500
A24: 22 | B24: 46131 | C24: Saif Bhai Kurla | D24: 374 | E24: 600 | F24: 224400 | G24: 3000 | H24: 242400 | I24: 50000 | J24: =+H24-I24 -> 192400
A25: 23 | B25: 46131 | C25: Saif Bhai Kurla | G25: 3000
A26: 24 | B26: 46131 | C26: Saif Bhai Kurla | G26: 3000
A27: 25 | B27: 46131 | C27: Saif Bhai Kurla | G27: 3000
A28: 26 | B28: 46131 | C28: Saif Bhai Kurla | G28: 3000
A29: 27 | B29: 46131 | C29: Saif Bhai Kurla | G29: 3000
A30: 28 | B30: 46131 | C30: Imtiyaz Bhai sakinaka | D30: 88 | E30: 625 | F30: 55000 | G30: 3500 | H30: 58500 | I30: 0 | J30: =+H30-I30 -> 58500
A31: 29 | B31: 46131 | C31: Faisal Sayyed | D31: 236 | E31: 600 | F31: 141600 | G31: 3500 | H31: 155600 | J31: =+H31-I31 -> 155600
A32: 30 | B32: 46131 | C32: Faisal Sayyed | G32: 3500
A33: 31 | B33: 46131 | C33: Faisal Sayyed | G33: 3500
A34: 32 | B34: 46131 | C34: Faisal Sayyed | G34: 3500
A35: 33 | B35: 46131 | C35: Nadeem bhai c/o Zain | D35: 118 | E35: 610 | F35: 71980 | G35: 3000 | H35: 77980 | I35: 35000 | J35: =+H35-I35 -> 42980
A36: 34 | B36: 46131 | C36: Nadeem bhai c/o Zain | G36: 3000
A37: 35 | B37: 46131 | C37: Mohd Faizaan Alaba | D37: 123 | E37: 626 | F37: 76998 | G37: 3500 | H37: 83998 | I37: 0 | J37: =+H37-I37 -> 83998
A38: 36 | B38: 46131 | C38: Mohd Faizaan Alaba | G38: 3500
A39: 37 | B39: 46134 | C39: Alishan Gesawat | D39: 226 | E39: 600 | F39: 135600 | G39: 3000 | H39: 144600 | I39: 0 | J39: =+H39-I39 -> 144600
A40: 38 | B40: 46134 | C40: Alishan Gesawat | G40: 3000
A41: 39 | B41: 46134 | C41: Alishan Gesawat | G41: 3000
...

Sheet Sale Combined
A1: Transportation cost | B1: =82000+82000 -> 164000 | C1: Rent | D1: =90000+80000 -> 170000 | E1: Palai days | F1: 46126 | G1: 46162 | H1: =+G1-F1 -> 36
A2: Total goat | B2: 170 | C2: Total goat | D2: 170 | E2: Palai per day | F2: 90 | G2: Palai per goat | H2: =+H3/F3 -> 2562.3529
A3: Per goat | B3: =+B1/B2 -> 964.70588 | C3: Per goat | D3: =+D1/D2 -> 1000 | E3: Total Goat | F3: 170 | G3: Total Palai 90 goats | H3: =+L171 -> 435600
A5: Sr No | B5: Date of Sale | C5: Name of the Buyer | D5: Weight | E5: Goat per Kg | F5: Goat Cost | G5: Transportation | H5: Rent | I5: Palai | J5: Total Cost | K5: Cost per kg | L5: Rate | M5: Amount | N5: Palai | O5: Total Amount | P5: Profit | Q5: Selling Rate | R5: Difference | S5: Profit
A6: 1 | B6: 46125 | C6: Guddu Bhai | D6: 83 | E6: 475 | F6: =+D6*E6 -> 39425 | G6: =+$B$3 -> 964.70588 | H6: =+$D$3 -> 1000 | I6: =+$H$2 -> 2562.3529 | J6: =+SUM(F6:I6) -> 43952.059 | K6: =+J6/D6 -> 529.54288 | L6: 600 | M6: =+D6*L6 -> 49800 | N6: 4000 | O6: =+M6+N6 -> 53800 | P6: =+O6-J6 -> 9847.9412 | Q6: =+O6/D6 -> 648.19277 | R6: =+Q6-K6 -> 118.64989 | S6: =+R6*D6 -> 9847.9412
A7: 2 | B7: 46126 | C7: Azam Kharghar | D7: 136 | E7: 475 | F7: =+D7*E7 -> 64600 | G7: =+$B$3 -> 964.70588 | H7: =+$D$3 -> 1000 | I7: =+$H$2 -> 2562.3529 | J7: =+F7+SUM(G7:I7)+SUM(G8:I8) -> 73654.118 | K7: =+J7/D7 -> 541.57439 | L7: 600 | M7: =+D7*L7 -> 81600 | N7: 4000 | O7: =+M7+N7+N8 -> 89600 | P7: =+O7-J7 -> 15945.882 | Q7: =+O7/D7 -> 658.82353 | R7: =+Q7-K7 -> 117.24913 | S7: =+R7*D7 -> 15945.882
A8: 3 | B8: 46126 | C8: Azam Kharghar | E8: 475 | G8: =+$B$3 -> 964.70588 | H8: =+$D$3 -> 1000 | I8: =+$H$2 -> 2562.3529 | N8: 4000
A9: 4 | B9: 46130 | C9: Salman Vikhroli | D9: 132 | E9: 475 | F9: =+D9*E9 -> 62700 | G9: =+$B$3 -> 964.70588 | H9: =+$D$3 -> 1000 | I9: =+$H$2 -> 2562.3529 | J9: =+F9+SUM(G9:I9)+SUM(G10:I10) -> 71754.118 | K9: =+J9/D9 -> 543.5918 | L9: 600 | M9: =+D9*L9 -> 79200 | N9: 3000 | O9: =+M9+N9+N10 -> 85200 | P9: =+O9-J9 -> 13445.882 | Q9: =+O9/D9 -> 645.45455 | R9: =+Q9-K9 -> 101.86275 | S9: =+R9*D9 -> 13445.882
A10: 5 | B10: 46130 | C10: Salman Vikhroli | E10: 475 | G10: =+$B$3 -> 964.70588 | H10: =+$D$3 -> 1000 | I10: =+$H$2 -> 2562.3529 | N10: 3000
A11: 6 | B11: 46130 | C11: Iqbal Bhai Khar | D11: 358 | E11: 475 | F11: =+D11*E11 -> 170050 | G11: =+$B$3 -> 964.70588 | H11: =+$D$3 -> 1000 | I11: =+$H$2 -> 2562.3529 | J11: =+F11+SUM(G11:G15)+SUM(H11:H15)+SUM(I11:I15) -> 192685.29 | K11: =+J11/D11 -> 538.22708 | L11: 600 | M11: =+D11*L11 -> 214800 | N11: 3000 | O11: =+M11+SUM(N11:N15) -> 229800 | P11: =+O11-J11 -> 37114.706 | Q11: =+O11/D11 -> 641.89944 | R11: =+Q11-K11 -> 103.67236 | S11: =+R11*D11 -> 37114.706
A12: 7 | B12: 46130 | C12: Iqbal Bhai Khar | E12: 475 | G12: =+$B$3 -> 964.70588 | H12: =+$D$3 -> 1000 | I12: =+$H$2 -> 2562.3529 | N12: 3000
A13: 8 | B13: 46130 | C13: Iqbal Bhai Khar | E13: 475 | G13: =+$B$3 -> 964.70588 | H13: =+$D$3 -> 1000 | I13: =+$H$2 -> 2562.3529 | N13: 3000
A14: 9 | B14: 46130 | C14: Iqbal Bhai Khar | E14: 475 | G14: =+$B$3 -> 964.70588 | H14: =+$D$3 -> 1000 | I14: =+$H$2 -> 2562.3529 | N14: 3000
A15: 10 | B15: 46130 | C15: Iqbal Bhai Khar | E15: 475 | G15: =+$B$3 -> 964.70588 | H15: =+$D$3 -> 1000 | I15: =+$H$2 -> 2562.3529 | N15: 3000
A16: 11 | B16: 46130 | C16: Sajid Bhai Jogeshwari | D16: 144 | E16: 475 | F16: =+D16*E16 -> 68400 | G16: =+$B$3 -> 964.70588 | H16: =+$D$3 -> 1000 | I16: =+$H$2 -> 2562.3529 | J16: =+F16+SUM(G16:I16)+SUM(G17:I17) -> 77454.118 | K16: =+J16/D16 -> 537.87582 | L16: 600 | M16: =+D16*L16 -> 86400 | N16: 3300 | O16: =+M16+N16+N17 -> 93000 | P16: =+O16-J16 -> 15545.882 | Q16: =+O16/D16 -> 645.83333 | R16: =+Q16-K16 -> 107.95752 | S16: =+R16*D16 -> 15545.882
A17: 12 | B17: 46130 | C17: Sajid Bhai Jogeshwari | E17: 475 | G17: =+$B$3 -> 964.70588 | H17: =+$D$3 -> 1000 | I17: =+$H$2 -> 2562.3529 | N17: 3300
A18: 13 | B18: 46130 | C18: Kashaf Bhai c/o Sarfaraz bhai | D18: 128 | E18: 475 | F18: =+D18*E18 -> 60800 | G18: =+$B$3 -> 964.70588 | H18: =+$D$3 -> 1000 | I18: =+$H$2 -> 2562.3529 | J18: =+F18+SUM(G18:I18)+SUM(G19:I19) -> 69854.118 | K18: =+J18/D18 -> 545.73529 | L18: 600 | M18: =+D18*L18 -> 76800 | N18: 3300 | O18: =+M18+N18+N19 -> 83400 | P18: =+O18-J18 -> 13545.882 | Q18: =+O18/D18 -> 651.5625 | R18: =+Q18-K18 -> 105.82721 | S18: =+R18*D18 -> 13545.882
A19: 14 | B19: 46130 | C19: Kashaf Bhai c/o Sarfaraz bhai | E19: 475 | G19: =+$B$3 -> 964.70588 | H19: =+$D$3 -> 1000 | I19: =+$H$2 -> 2562.3529 | N19: 3300
A20: 15 | B20: 46131 | C20: Mohd Faizaan | D20: 123 | E20: 475 | F20: =+D20*E20 -> 58425 | G20: =+$B$3 -> 964.70588 | H20: =+$D$3 -> 1000 | I20: =+$H$2 -> 2562.3529 | J20: =+F20+SUM(G20:I20)+SUM(G21:I21) -> 67479.118 | K20: =+J20/D20 -> 548.61071 | L20: 626.017 | M20: =+D20*L20 -> 77000.091 | N20: 3500 | O20: =+SUM(M20+N20+N21) -> 84000.091 | P20: =+O20-J20 -> 16520.973 | Q20: =+O20/D20 -> 682.92757 | R20: =+Q20-K20 -> 134.31686 | S20: =+R20*D20 -> 16520.973
A21: 16 | B21: 46131 | C21: Mohd Faizaan | E21: 475 | G21: =+$B$3 -> 964.70588 | H21: =+$D$3 -> 1000 | I21: =+$H$2 -> 2562.3529 | M21: =+D21*L21 -> 0 | N21: 3500
A22: 17 | B22: 46131 | C22: Salman Akhlak | D22: 115 | E22: 475 | F22: =+D22*E22 -> 54625 | G22: =+$B$3 -> 964.70588 | H22: =+$D$3 -> 1000 | I22: =+$H$2 -> 2562.3529 | J22: =+SUM(F22+SUM(G22:I22)+SUM(G23:I23)) -> 63679.118 | K22: =+J22/D22 -> 553.73146 | L22: 600 | M22: =+D22*L22 -> 69000 | N22: 3000 | O22: =+M22+N22+N23 -> 75000 | P22: =+O22-J22 -> 11320.882 | Q22: =+O22/D22 -> 652.17391 | R22: =+Q22-K22 -> 98.442455 | S22: =+R22*D22 -> 11320.882
A23: 18 | B23: 46131 | C23: Salman Akhlak | E23: 475 | G23: =+$B$3 -> 964.70588 | H23: =+$D$3 -> 1000 | I23: =+$H$2 -> 2562.3529 | N23: 3000
A24: 19 | B24: 46131 | C24: Shahid Shaikh Kurla | D24: 136 | E24: 475 | F24: =+D24*E24 -> 64600 | G24: =+$B$3 -> 964.70588 | H24: =+$D$3 -> 1000 | I24: =+$H$2 -> 2562.3529 | J24: =+F24+SUM(G24:I24)+SUM(G25:I25) -> 73654.118 | K24: =+J24/D24 -> 541.57439 | L24: 600 | M24: =+D24*L24 -> 81600 | N24: 3400 | O24: =+M24+N24+N25 -> 88400 | P24: =+O24-J24 -> 14745.882 | Q24: =+O24/D24 -> 650 | R24: =+Q24-K24 -> 108.42561 | S24: =+R24*D24 -> 14745.882
A25: 20 | B25: 46131 | C25: Shahid Shaikh Kurla | E25: 475 | G25: =+$B$3 -> 964.70588 | H25: =+$D$3 -> 1000 | I25: =+$H$2 -> 2562.3529 | N25: 3400
A26: 21 | B26: 46131 | C26: Shahid Shaikh Kurla | D26: 63 | E26: 475 | F26: =+D26*E26 -> 29925 | G26: =+$B$3 -> 964.70588 | H26: =+$D$3 -> 1000 | I26: =+$H$2 -> 2562.3529 | J26: =+SUM(F26:I26) -> 34452.059 | K26: =+J26/D26 -> 546.85808 | L26: 700 | M26: =+L26*D26 -> 44100 | N26: 3400 | O26: =+M26+N26 -> 47500 | P26: =+O26-J26 -> 13047.941 | Q26: =+O26/D26 -> 753.96825 | R26: =+Q26-K26 -> 207.11018 | S26: =+R26*D26 -> 13047.941
A27: 22 | B27: 46131 | C27: Saif Bhai Kurla | D27: 374 | E27: 475 | F27: =+D27*E27 -> 177650 | G27: =+$B$3 -> 964.70588 | H27: =+$D$3 -> 1000 | I27: =+$H$2 -> 2562.3529 | J27: =+SUM(F27+SUM(G27:G32)+SUM(H27:H32)+SUM(I27:I32)) -> 204812.35 | K27: =+J27/D27 -> 547.62661 | L27: 600 | M27: =+D27*L27 -> 224400 | N27: 3000 | O27: =+M27+SUM(N27:N32) -> 242400 | P27: =+O27-J27 -> 37587.647 | Q27: =+O27/D27 -> 648.12834 | R27: =+Q27-K27 -> 100.50173 | S27: =+R27*D27 -> 37587.647
A28: 23 | B28: 46131 | C28: Saif Bhai Kurla | E28: 475 | G28: =+$B$3 -> 964.70588 | H28: =+$D$3 -> 1000 | I28: =+$H$2 -> 2562.3529 | N28: 3000
A29: 24 | B29: 46131 | C29: Saif Bhai Kurla | E29: 475 | G29: =+$B$3 -> 964.70588 | H29: =+$D$3 -> 1000 | I29: =+$H$2 -> 2562.3529 | N29: 3000
A30: 25 | B30: 46131 | C30: Saif Bhai Kurla | E30: 475 | G30: =+$B$3 -> 964.70588 | H30: =+$D$3 -> 1000 | I30: =+$H$2 -> 2562.3529 | N30: 3000
A31: 26 | B31: 46131 | C31: Saif Bhai Kurla | E31: 475 | G31: =+$B$3 -> 964.70588 | H31: =+$D$3 -> 1000 | I31: =+$H$2 -> 2562.3529 | N31: 3000
A32: 27 | B32: 46131 | C32: Saif Bhai Kurla | E32: 475 | G32: =+$B$3 -> 964.70588 | H32: =+$D$3 -> 1000 | I32: =+$H$2 -> 2562.3529 | N32: 3000
A33: 28 | B33: 46131 | C33: Imtiyaz Bhai sakinaka | D33: 88 | E33: 475 | F33: =+D33*E33 -> 41800 | G33: =+$B$3 -> 964.70588 | H33: =+$D$3 -> 1000 | I33: =+$H$2 -> 2562.3529 | J33: =+SUM(F33:I33) -> 46327.059 | K33: =+J33/D33 -> 526.44385 | L33: 625 | M33: =+L33*D33 -> 55000 | N33: 3500 | O33: =+M33+N33 -> 58500 | P33: =+O33-J33 -> 12172.941 | Q33: =+O33/D33 -> 664.77273 | R33: =+Q33-K33 -> 138.32888 | S33: =+R33*D33 -> 12172.941
A34: 29 | B34: 46131 | C34: Faisal Sayyed | D34: 236 | E34: 475 | F34: =+D34*E34 -> 112100 | G34: =+$B$3 -> 964.70588 | H34: =+$D$3 -> 1000 | I34: =+$H$2 -> 2562.3529 | J34: =+F34+SUM(G34:G37)+SUM(H34:H37)+SUM(I34:I37) -> 130208.24 | K34: =+J34/D34 -> 551.72981 | L34: 600 | M34: =+D34*L34 -> 141600 | N34: 3500 | O34: =+M34+SUM(N34:N37) -> 155600 | P34: =+O34-J34 -> 25391.765 | Q34: =+O34/D34 -> 659.32203 | R34: =+Q34-K34 -> 107.59222 | S34: =+R34*D34 -> 25391.765
A35: 30 | B35: 46131 | C35: Faisal Sayyed | E35: 475 | G35: =+$B$3 -> 964.70588 | H35: =+$D$3 -> 1000 | I35: =+$H$2 -> 2562.3529 | N35: 3500
A36: 31 | B36: 46131 | C36: Faisal Sayyed | E36: 475 | G36: =+$B$3 -> 964.70588 | H36: =+$D$3 -> 1000 | I36: =+$H$2 -> 2562.3529 | N36: 3500
A37: 32 | B37: 46131 | C37: Faisal Sayyed | E37: 475 | G37: =+$B$3 -> 964.70588 | H37: =+$D$3 -> 1000 | I37: =+$H$2 -> 2562.3529 | N37: 3500
A38: 33 | B38: 46131 | C38: Nadeem bhai c/o Zain | D38: 118 | E38: 475 | F38: =+D38*E38 -> 56050 | G38: =+$B$3 -> 964.70588 | H38: =+$D$3 -> 1000 | I38: =+$H$2 -> 2562.3529 | J38: =+F38+SUM(G38:I38)+SUM(G39:I39) -> 65104.118 | K38: =+J38/D38 -> 551.72981 | L38: 610 | M38: =+D38*L38 -> 71980 | N38: 3000 | O38: =+M38+N38+N39 -> 77980 | P38: =+O38-J38 -> 12875.882 | Q38: =+O38/D38 -> 660.84746 | R38: =+Q38-K38 -> 109.11765 | S38: =+R38*D38 -> 12875.882
A39: 34 | B39: 46131 | C39: Nadeem bhai c/o Zain | E39: 475 | G39: =+$B$3 -> 964.70588 | H39: =+$D$3 -> 1000 | I39: =+$H$2 -> 2562.3529 | N39: 3000
A40: 35 | B40: 46131 | C40: Mohd Faizaan Alaba | D40: 123 | E40: 475 | F40: =+D40*E40 -> 58425 | G40: =+$B$3 -> 964.70588 | H40: =+$D$3 -> 1000 | I40: =+$H$2 -> 2562.3529 | J40: =+F40+SUM(G40:I41) -> 67479.118 | K40: =+J40/D40 -> 548.61071 | L40: 626 | M40: =+D40*L40 -> 76998 | N40: 3500 | O40: =+M40+N40+N41 -> 83998 | P40: =+O40-J40 -> 16518.882 | Q40: =+O40/D40 -> 682.91057 | R40: =+Q40-K40 -> 134.29986 | S40: =+R40*D40 -> 16518.882
A41: 36 | B41: 46131 | C41: Mohd Faizaan Alaba | E41: 475 | G41: =+$B$3 -> 964.70588 | H41: =+$D$3 -> 1000 | I41: =+$H$2 -> 2562.3529 | N41: 3500
...

Sheet Lot 1 weight list
A1: Sr No | B1: Weight | C1: Sr No | D1: Weight | E1: Sr No | F1: Weight | G1: Sr No | H1: Weight
A2: 1 | B2: 54 | C2: 26 | D2: 65 | E2: 51 | F2: 70 | G2: 76 | H2: 76
A3: 2 | B3: 56 | C3: 27 | D3: 66 | E3: 52 | F3: 70 | G3: 77 | H3: 76
A4: 3 | B4: 57 | C4: 28 | D4: 66 | E4: 53 | F4: 70 | G4: 78 | H4: 77 | O4: 1
A5: 4 | B5: 57 | C5: 29 | D5: 66 | E5: 54 | F5: 70 | G5: 79 | H5: 77 | O5: 2
A6: 5 | B6: 57 | C6: 30 | D6: 66 | E6: 55 | F6: 70 | G6: 80 | H6: 77 | O6: 2
A7: 6 | B7: 58 | C7: 31 | D7: 66 | E7: 56 | F7: 71 | G7: 81 | H7: 77 | O7: 5
A8: 7 | B8: 58 | C8: 32 | D8: 67 | E8: 57 | F8: 71 | G8: 82 | H8: 77 | O8: 2
A9: 8 | B9: 59 | C9: 33 | D9: 67 | E9: 58 | F9: 71 | G9: 83 | H9: 78 | O9: 2
A10: 9 | B10: 59 | C10: 34 | D10: 67 | E10: 59 | F10: 71 | G10: 84 | H10: 80 | O10: 2
A11: 10 | B11: 60 | C11: 35 | D11: 67 | E11: 60 | F11: 71 | G11: 85 | H11: 82 | O11: 2
A12: 11 | B12: 60 | C12: 36 | D12: 67 | E12: 61 | F12: 71 | G12: 86 | H12: 84 | O12: 3
A13: 12 | B13: 60 | C13: 37 | D13: 68 | E13: 62 | F13: 72 | G13: 87 | H13: 85 | O13: 6
A14: 13 | B14: 61 | C14: 38 | D14: 68 | E14: 63 | F14: 72 | G14: 88 | H14: 85 | O14: 1
A15: 14 | B15: 61 | C15: 39 | D15: 68 | E15: 64 | F15: 72 | G15: 89 | H15: 86 | O15: 4
A16: 15 | B16: 62 | C16: 40 | D16: 68 | E16: 65 | F16: 72 | G16: 90 | H16: 91 | O16: 2 | R16: =90*585 -> 52650 | T16: 580 | U16: 590 | V16: 580
A17: 16 | B17: 62 | C17: 41 | D17: 68 | E17: 66 | F17: 73 | O17: 3 | T17: 88 | U17: 88 | V17: 90
A18: 17 | B18: 62 | C18: 42 | D18: 68 | E18: 67 | F18: 73 | O18: 5 | T18: =+T16*T17 -> 51040 | U18: =+U16*U17 -> 51920 | V18: =+V16*V17 -> 52200
A19: 18 | B19: 62 | C19: 43 | D19: 68 | E19: 68 | F19: 73 | O19: 1
A20: 19 | B20: 62 | C20: 44 | D20: 69 | E20: 69 | F20: 74 | O20: 3
A21: 20 | B21: 63 | C21: 45 | D21: 69 | E21: 70 | F21: 74 | O21: 4
A22: 21 | B22: 63 | C22: 46 | D22: 69 | E22: 71 | F22: 74 | O22: 2
A23: 22 | B23: 63 | C23: 47 | D23: 69 | E23: 72 | F23: 74 | L23: =82*78 -> 6396 | O23: 2
A24: 23 | B24: 63 | C24: 48 | D24: 70 | E24: 73 | F24: 75 | O24: 6
A25: 24 | B25: 64 | C25: 49 | D25: 70 | E25: 74 | F25: 75 | O25: 1
A26: 25 | B26: 65 | C26: 50 | D26: 70 | E26: 75 | F26: 76 | K26: Lot 1 | L26: Lot 2 | O26: 2
B27: =+SUM(B2:B26) -> 1508 | D27: =+SUM(D2:D26) -> 1692 | F27: =+SUM(F2:F26) -> 1805 | H27: =+SUM(H2:H26) -> 1208 | J27: =+L27+K27 -> 12487 | K27: =+SUM(A27:I27) -> 6213 | L27: =6424-150 -> 6274 | M27: 2 goats deducted from Ferozhai sale | O27: 3
K28: 475 | L28: 530 | O28: 4
J29: =+L29+K29 -> 6276395 | K29: =+K27*K28 -> 2951175 | L29: =+L27*L28 -> 3325220 | O29: 2
O30: 2
O31: 16
O32: 4
O33: 3
O34: 4
O35: 3
O36: 4
O39: =+SUM(O1:O38) -> 108
O40: 170
O41: =+O40-O39 -> 62
D88: 515 | E88: 14 | F88: 70 | G88: =+E88*F88 -> 980
...

Sheet Sheet10
A1: Sr No | B1: Date of Sale | E1: Row Labels | F1: Count of Date of Sale
A2: 1 | B2: 46125 | E2: 46125 | F2: 1
A3: 2 | B3: 46126 | E3: 46126 | F3: 2
A4: 3 | B4: 46126 | E4: 46130 | F4: 11
A5: 4 | B5: 46130 | E5: 46131 | F5: 22
A6: 5 | B6: 46130 | E6: 46134 | F6: 3
A7: 6 | B7: 46130 | E7: 46137 | F7: 5
A8: 7 | B8: 46130 | E8: 46138 | F8: 10
A9: 8 | B9: 46130 | E9: 46142 | F9: 8
A10: 9 | B10: 46130 | E10: 46143 | F10: 10
A11: 10 | B11: 46130 | E11: 46144 | F11: 4
A12: 11 | B12: 46130 | E12: 46145 | F12: 16
A13: 12 | B13: 46130 | E13: 46146 | F13: 3
... A17: 16 | B17: 46131 | E17: 46152 | F17: 7
A18: 17 | B18: 46131 | E18: Grand Total | F18: 120
A19: 18 | B19: 46131
A20: 19 | B20: 46131
A21: 20 | B21: 46131
A22: 21 | B22: 46131
A23: 22 | B23: 46131
A24: 23 | B24: 46131
A25: 24 | B25: 46131
A26: 25 | B26: 46131
A27: 26 | B27: 46131
A28: 27 | B28: 46131
A29: 28 | B29: 46131
A30: 29 | B30: 46131
... A121: 120 | B121: 46152

Sheet Lot 1 sale Seperate
A1: Transportation cost | B1: 82000 | C1: Rent | D1: 90000 | E1: Palai days | F1: 46126 | G1: 46162 | H1: =+G1-F1 -> 36
A2: Total goat | B2: 90 | C2: Total goat | D2: 90 | E2: Palai per day | F2: 90 | G2: Palai per goat | H2: =+F2*H1 -> 3240
A3: Per goat | B3: =+B1/B2 -> 911.11111 | C3: Per goat | D3: =+D1/D2 -> 1000 | E3: Total Goat | F3: 90 | G3: Total Palai 90 goats | H3: =+H1*F2*F3 -> 291600
A5: Sr No | B5: Date of Sale | C5: Name of the Buyer | D5: Weight | E5: Goat per Kg | F5: Goat Cost | G5: Transportation | H5: Rent | I5: Palai | J5: Total Cost | K5: Cost per kg | L5: Rate | M5: Amount | N5: Palai | O5: Total Amount | P5: Profit | Q5: Selling Rate | R5: Difference | S5: Profit
A6: 1 | B6: 46125 | C6: Guddu Bhai | D6: 83 | E6: 475 | F6: =+D6*E6 -> 39425 | G6: =+$B$3 -> 911.11111 | H6: =+$D$3 -> 1000 | I6: =+$H$2 -> 3240 | J6: =+SUM(F6:I6) -> 44576.111 | K6: =+J6/D6 -> 537.06158 | L6: 600 | M6: =+D6*L6 -> 49800 | N6: 4000 | O6: =+M6+N6 -> 53800 | P6: =+O6-J6 -> 9223.8889 | Q6: =+O6/D6 -> 648.19277 | R6: =+Q6-K6 -> 111.13119 | S6: =+R6*D6 -> 9223.8889
A7: 2 | B7: 46126 | C7: Azam Kharghar | D7: 136 | E7: 475 | F7: =+D7*E7 -> 64600 | G7: =+$B$3 -> 911.11111 | H7: =+$D$3 -> 1000 | I7: =+$H$2 -> 3240 | J7: =+F7+SUM(G7:I7)+SUM(G8:I8) -> 74902.222 | K7: =+J7/D7 -> 550.75163 | L7: 600 | M7: =+D7*L7 -> 81600 | N7: 4000 | O7: =+M7+N7+N8 -> 89600 | P7: =+O7-J7 -> 14697.778 | Q7: =+O7/D7 -> 658.82353 | R7: =+Q7-K7 -> 108.0719 | S7: =+R7*D7 -> 14697.778
A8: 3 | B8: 46126 | C8: Azam Kharghar | E8: 475 | G8: =+$B$3 -> 911.11111 | H8: =+$D$3 -> 1000 | I8: =+$H$2 -> 3240 | N8: 4000
A9: 4 | B9: 46130 | C9: Salman Vikhroli | D9: 132 | E9: 475 | F9: =+D9*E9 -> 62700 | G9: =+$B$3 -> 911.11111 | H9: =+$D$3 -> 1000 | I9: =+$H$2 -> 3240 | J9: =+F9+SUM(G9:I9)+SUM(G10:I10) -> 73002.222 | K9: =+J9/D9 -> 553.04714 | L9: 600 | M9: =+D9*L9 -> 79200 | N9: 3000 | O9: =+M9+N9+N10 -> 85200 | P9: =+O9-J9 -> 12197.778 | Q9: =+O9/D9 -> 645.45455 | R9: =+Q9-K9 -> 92.407407 | S9: =+R9*D9 -> 12197.778
A10: 5 | B10: 46130 | C10: Salman Vikhroli | E10: 475 | G10: =+$B$3 -> 911.11111 | H10: =+$D$3 -> 1000 | I10: =+$H$2 -> 3240 | N10: 3000
A11: 6 | B11: 46130 | C11: Iqbal Bhai Khar | D11: 358 | E11: 475 | F11: =+D11*E11 -> 170050 | G11: =+$B$3 -> 911.11111 | H11: =+$D$3 -> 1000 | I11: =+$H$2 -> 3240 | J11: =+F11+SUM(G11:G15)+SUM(H11:H15)+SUM(I11:I15) -> 195805.56 | K11: =+J11/D11 -> 546.94289 | L11: 600 | M11: =+D11*L11 -> 214800 | N11: 3000 | O11: =+M11+SUM(N11:N15) -> 229800 | P11: =+O11-J11 -> 33994.444 | Q11: =+O11/D11 -> 641.89944 | R11: =+Q11-K11 -> 94.956549 | S11: =+R11*D11 -> 33994.444
A12: 7 | B12: 46130 | C12: Iqbal Bhai Khar | E12: 475 | G12: =+$B$3 -> 911.11111 | H12: =+$D$3 -> 1000 | I12: =+$H$2 -> 3240 | N12: 3000
A13: 8 | B13: 46130 | C13: Iqbal Bhai Khar | E13: 475 | G13: =+$B$3 -> 911.11111 | H13: =+$D$3 -> 1000 | I13: =+$H$2 -> 3240 | N13: 3000
A14: 9 | B14: 46130 | C14: Iqbal Bhai Khar | E14: 475 | G14: =+$B$3 -> 911.11111 | H14: =+$D$3 -> 1000 | I14: =+$H$2 -> 3240 | N14: 3000
A15: 10 | B15: 46130 | C15: Iqbal Bhai Khar | E15: 475 | G15: =+$B$3 -> 911.11111 | H15: =+$D$3 -> 1000 | I15: =+$H$2 -> 3240 | N15: 3000
A16: 11 | B16: 46130 | C16: Sajid Bhai Jogeshwari | D16: 144 | E16: 475 | F16: =+D16*E16 -> 68400 | G16: =+$B$3 -> 911.11111 | H16: =+$D$3 -> 1000 | I16: =+$H$2 -> 3240 | J16: =+F16+SUM(G16:I16)+SUM(G17:I17) -> 78702.222 | K16: =+J16/D16 -> 546.54321 | L16: 600 | M16: =+D16*L16 -> 86400 | N16: 3300 | O16: =+M16+N16+N17 -> 93000 | P16: =+O16-J16 -> 14297.778 | Q16: =+O16/D16 -> 645.83333 | R16: =+Q16-K16 -> 99.290123 | S16: =+R16*D16 -> 14297.778
A17: 12 | B17: 46130 | C17: Sajid Bhai Jogeshwari | E17: 475 | G17: =+$B$3 -> 911.11111 | H17: =+$D$3 -> 1000 | I17: =+$H$2 -> 3240 | N17: 3300
A18: 13 | B18: 46130 | C18: Kashaf Bhai c/o Sarfaraz bhai | D18: 128 | E18: 475 | F18: =+D18*E18 -> 60800 | G18: =+$B$3 -> 911.11111 | H18: =+$D$3 -> 1000 | I18: =+$H$2 -> 3240 | J18: =+F18+SUM(G18:I18)+SUM(G19:I19) -> 71102.222 | K18: =+J18/D18 -> 555.48611 | L18: 600 | M18: =+D18*L18 -> 76800 | N18: 3300 | O18: =+M18+N18+N19 -> 83400 | P18: =+O18-J18 -> 12297.778 | Q18: =+O18/D18 -> 651.5625 | R18: =+Q18-K18 -> 96.076389 | S18: =+R18*D18 -> 12297.778
A19: 14 | B19: 46130 | C19: Kashaf Bhai c/o Sarfaraz bhai | E19: 475 | G19: =+$B$3 -> 911.11111 | H19: =+$D$3 -> 1000 | I19: =+$H$2 -> 3240 | N19: 3300
A20: 15 | B20: 46131 | C20: Mohd Faizaan | D20: 123 | E20: 475 | F20: =+D20*E20 -> 58425 | G20: =+$B$3 -> 911.11111 | H20: =+$D$3 -> 1000 | I20: =+$H$2 -> 3240 | J20: =+F20+SUM(G20:I20)+SUM(G21:I21) -> 68727.222 | K20: =+J20/D20 -> 558.7579 | L20: 626.017 | M20: =+D20*L20 -> 77000.091 | N20: 3500 | O20: =+SUM(M20+N20+N21) -> 84000.091 | P20: =+O20-J20 -> 15272.869 | Q20: =+O20/D20 -> 682.92757 | R20: =+Q20-K20 -> 124.16966 | S20: =+R20*D20 -> 15272.869
A21: 16 | B21: 46131 | C21: Mohd Faizaan | E21: 475 | G21: =+$B$3 -> 911.11111 | H21: =+$D$3 -> 1000 | I21: =+$H$2 -> 3240 | M21: =+D21*L21 -> 0 | N21: 3500
A22: 17 | B22: 46131 | C22: Salman Akhlak | D22: 115 | E22: 475 | F22: =+D22*E22 -> 54625 | G22: =+$B$3 -> 911.11111 | H22: =+$D$3 -> 1000 | I22: =+$H$2 -> 3240 | J22: =+SUM(F22+SUM(G22:I22)+SUM(G23:I23)) -> 64927.222 | K22: =+J22/D22 -> 564.58454 | L22: 600 | M22: =+D22*L22 -> 69000 | N22: 3000 | O22: =+M22+N22+N23 -> 75000 | P22: =+O22-J22 -> 10072.778 | Q22: =+O22/D22 -> 652.17391 | R22: =+Q22-K22 -> 87.589372 | S22: =+R22*D22 -> 10072.778
A23: 18 | B23: 46131 | C23: Salman Akhlak | E23: 475 | G23: =+$B$3 -> 911.11111 | H23: =+$D$3 -> 1000 | I23: =+$H$2 -> 3240 | N23: 3000
A24: 19 | B24: 46131 | C24: Shahid Shaikh Kurla | D24: 136 | E24: 475 | F24: =+D24*E24 -> 64600 | G24: =+$B$3 -> 911.11111 | H24: =+$D$3 -> 1000 | I24: =+$H$2 -> 3240 | J24: =+F24+SUM(G24:I24)+SUM(G25:I25) -> 74902.222 | K24: =+J24/D24 -> 550.75163 | L24: 600 | M24: =+D24*L24 -> 81600 | N24: 3400 | O24: =+M24+N24+N25 -> 88400 | P24: =+O24-J24 -> 13497.778 | Q24: =+O24/D24 -> 650 | R24: =+Q24-K24 -> 99.248366 | S24: =+R24*D24 -> 13497.778
A25: 20 | B25: 46131 | C25: Shahid Shaikh Kurla | E25: 475 | G25: =+$B$3 -> 911.11111 | H25: =+$D$3 -> 1000 | I25: =+$H$2 -> 3240 | N25: 3400
A26: 21 | B26: 46131 | C26: Shahid Shaikh Kurla | D26: 63 | E26: 475 | F26: =+D26*E26 -> 29925 | G26: =+$B$3 -> 911.11111 | H26: =+$D$3 -> 1000 | I26: =+$H$2 -> 3240 | J26: =+SUM(F26:I26) -> 35076.111 | K26: =+J26/D26 -> 556.76367 | L26: 700 | M26: =+L26*D26 -> 44100 | N26: 3400 | O26: =+M26+N26 -> 47500 | P26: =+O26-J26 -> 12423.889 | Q26: =+O26/D26 -> 753.96825 | R26: =+Q26-K26 -> 197.20459 | S26: =+R26*D26 -> 12423.889
A27: 22 | B27: 46131 | C27: Saif Bhai Kurla | D27: 374 | E27: 475 | F27: =+D27*E27 -> 177650 | G27: =+$B$3 -> 911.11111 | H27: =+$D$3 -> 1000 | I27: =+$H$2 -> 3240 | J27: =+SUM(F27+SUM(G27:G32)+SUM(H27:H32)+SUM(I27:I32)) -> 208556.67 | K27: =+J27/D27 -> 557.63815 | L27: 600 | M27: =+D27*L27 -> 224400 | N27: 3000 | O27: =+M27+SUM(N27:N32) -> 242400 | P27: =+O27-J27 -> 33843.333 | Q27: =+O27/D27 -> 648.12834 | R27: =+Q27-K27 -> 90.490196 | S27: =+R27*D27 -> 33843.333
A28: 23 | B28: 46131 | C28: Saif Bhai Kurla | E28: 475 | G28: =+$B$3 -> 911.11111 | H28: =+$D$3 -> 1000 | I28: =+$H$2 -> 3240 | N28: 3000
A29: 24 | B29: 46131 | C29: Saif Bhai Kurla | E29: 475 | G29: =+$B$3 -> 911.11111 | H29: =+$D$3 -> 1000 | I29: =+$H$2 -> 3240 | N29: 3000
A30: 25 | B30: 46131 | C30: Saif Bhai Kurla | E30: 475 | G30: =+$B$3 -> 911.11111 | H30: =+$D$3 -> 1000 | I30: =+$H$2 -> 3240 | N30: 3000
A31: 26 | B31: 46131 | C31: Saif Bhai Kurla | E31: 475 | G31: =+$B$3 -> 911.11111 | H31: =+$D$3 -> 1000 | I31: =+$H$2 -> 3240 | N31: 3000
A32: 27 | B32: 46131 | C32: Saif Bhai Kurla | E32: 475 | G32: =+$B$3 -> 911.11111 | H32: =+$D$3 -> 1000 | I32: =+$H$2 -> 3240 | N32: 3000
A33: 28 | B33: 46131 | C33: Imtiyaz Bhai sakinaka | D33: 88 | E33: 475 | F33: =+D33*E33 -> 41800 | G33: =+$B$3 -> 911.11111 | H33: =+$D$3 -> 1000 | I33: =+$H$2 -> 3240 | J33: =+SUM(F33:I33) -> 46951.111 | K33: =+J33/D33 -> 533.53535 | L33: 625 | M33: =+L33*D33 -> 55000 | N33: 3500 | O33: =+M33+N33 -> 58500 | P33: =+O33-J33 -> 11548.889 | Q33: =+O33/D33 -> 664.77273 | R33: =+Q33-K33 -> 131.23737 | S33: =+R33*D33 -> 11548.889
A34: 29 | B34: 46131 | C34: Faisal Sayyed | D34: 236 | E34: 475 | F34: =+D34*E34 -> 112100 | G34: =+$B$3 -> 911.11111 | H34: =+$D$3 -> 1000 | I34: =+$H$2 -> 3240 | J34: =+F34+SUM(G34:G37)+SUM(H34:H37)+SUM(I34:I37) -> 132704.44 | K34: =+J34/D34 -> 562.30697 | L34: 600 | M34: =+D34*L34 -> 141600 | N34: 3500 | O34: =+M34+SUM(N34:N37) -> 155600 | P34: =+O34-J34 -> 22895.556 | Q34: =+O34/D34 -> 659.32203 | R34: =+Q34-K34 -> 97.015066 | S34: =+R34*D34 -> 22895.556
A35: 30 | B35: 46131 | C35: Faisal Sayyed | E35: 475 | G35: =+$B$3 -> 911.11111 | H35: =+$D$3 -> 1000 | I35: =+$H$2 -> 3240 | N35: 3500
A36: 31 | B36: 46131 | C36: Faisal Sayyed | E36: 475 | G36: =+$B$3 -> 911.11111 | H36: =+$D$3 -> 1000 | I36: =+$H$2 -> 3240 | N36: 3500
A37: 32 | B37: 46131 | C37: Faisal Sayyed | E37: 475 | G37: =+$B$3 -> 911.11111 | H37: =+$D$3 -> 1000 | I37: =+$H$2 -> 3240 | N37: 3500
A38: 33 | B38: 46131 | C38: Nadeem bhai c/o Zain | D38: 118 | E38: 475 | F38: =+D38*E38 -> 56050 | G38: =+$B$3 -> 911.11111 | H38: =+$D$3 -> 1000 | I38: =+$H$2 -> 3240 | J38: =+F38+SUM(G38:I38)+SUM(G39:I39) -> 66352.222 | K38: =+J38/D38 -> 562.30697 | L38: 610 | M38: =+D38*L38 -> 71980 | N38: 3000 | O38: =+M38+N38+N39 -> 77980 | P38: =+O38-J38 -> 11627.778 | Q38: =+O38/D38 -> 660.84746 | R38: =+Q38-K38 -> 98.54049 | S38: =+R38*D38 -> 11627.778
A39: 34 | B39: 46131 | C39: Nadeem bhai c/o Zain | E39: 475 | G39: =+$B$3 -> 911.11111 | H39: =+$D$3 -> 1000 | I39: =+$H$2 -> 3240 | N39: 3000
A40: 35 | B40: 46131 | C40: Mohd Faizaan Alaba | D40: 123 | E40: 475 | F40: =+D40*E40 -> 58425 | G40: =+$B$3 -> 911.11111 | H40: =+$D$3 -> 1000 | I40: =+$H$2 -> 3240 | J40: =+F40+SUM(G40:I41) -> 68727.222 | K40: =+J40/D40 -> 558.7579 | L40: 626 | M40: =+D40*L40 -> 76998 | N40: 3500 | O40: =+M40+N40+N41 -> 83998 | P40: =+O40-J40 -> 15270.778 | Q40: =+O40/D40 -> 682.91057 | R40: =+Q40-K40 -> 124.15266 | S40: =+R40*D40 -> 15270.778
A41: 36 | B41: 46131 | C41: Mohd Faizaan Alaba | E41: 475 | G41: =+$B$3 -> 911.11111 | H41: =+$D$3 -> 1000 | I41: =+$H$2 -> 3240 | N41: 3500
...

Sheet Sheet5
A1: 82
A2: 66
A3: 71
A4: 67
A5: 68
A6: 83
A7: 77
A8: 71
A9: 64
A10: 67
A11: 67
A12: 64
... A56: 71
A58: =SUM(A1:A57) -> 3963

Sheet HKB
G1: HKB | H1: 120000 | I1: Jamil | J1: 50000 | K1: Labour | L1: 30000 | M1: other exp | N1: 30000
C4: Gujri | D4: Sojat | E4: Total | H4: Gujri | I4: Sojat | J4: Sojat | K4: Total | N4: Gujri | O4: Sojat | P4: Sojat Big | Q4: Total | T4: Gujri | U4: Sojat | V4: Total
B5: No Of Goats | C5: 50 | D5: 67 | E5: =+C5+D5 -> 117 | G5: No Of Goats | H5: 50 | I5: 67 | J5: 29 | K5: =+SUM(H5:J5) -> 146 | M5: No Of Goats | N5: 50 | O5: 67 | P5: 24 | Q5: =+SUM(N5:P5) -> 141 | S5: No Of Goats | T5: 50 | U5: 94 | V5: =+SUM(T5:U5) -> 144
B6: Weight Patti | C6: 73 | D6: 71 | G6: Weight Patti | H6: 73 | I6: 73 | J6: 74 | K6: =+AVERAGE(H6:J6) -> 73.333333 | M6: Weight Patti | N6: 70 | O6: 73 | P6: 90 | Q6: =+AVERAGE(N6:P6) -> 77.666667 | S6: Weight Patti | T6: 73 | U6: 74 | V6: =+AVERAGE(T6:U6) -> 73.5
B7: total Wgt | C7: =+C5*C6 -> 3650 | D7: 4781 | E7: =+C7+D7 -> 8431 | G7: total Wgt | H7: =+H5*H6 -> 3650 | I7: 4781 | J7: 2199 | K7: =+SUM(H7:J7) -> 10630 | M7: total Wgt | N7: =+N5*N6 -> 3500 | O7: 4781 | P7: =+P5*P6 -> 2160 | Q7: =+SUM(N7:P7) -> 10441 | S7: total Wgt | T7: =+T5*T6 -> 3650 | U7: 6944 | V7: =+SUM(T7:U7) -> 10594 | X7: =+#REF!+#REF! -> #REF!
B8: Cost Rate | C8: 475 | D8: 530 | G8: Cost Rate | H8: 475 | I8: 530 | J8: 535 | K8: =+SUM(H8:J8) -> 1540 | M8: Cost Rate | N8: 475 | O8: 530 | P8: 605 | Q8: =+SUM(N8:P8) -> 1610 | S8: Cost Rate | T8: 475 | U8: 532 | V8: =+SUM(T8:U8) -> 1007 | X8: =+#REF!+#REF! -> #REF!
B9: Cost % to weight | C9: =+C7/E7 -> 0.43292611 | D9: =+D7/E7 -> 0.56707389 | E9: =+C9+D9 -> 1 | G9: Cost % to weight | H9: =+H7/$K$7 -> 0.34336783 | I9: =+I7/$K$7 -> 0.44976482 | J9: =+J7/$K$7 -> 0.20686736 | K9: =+SUM(H9:J9) -> 1 | M9: Cost % to weight | N9: =+N7/$K$7 -> 0.32925682 | O9: =+O7/$K$7 -> 0.44976482 | P9: =+P7/$K$7 -> 0.20319849 | Q9: =+SUM(N9:P9) -> 0.98222013 | S9: Cost % to weight | T9: =+T7/V7 -> 0.34453464 | U9: =+U7/V7 -> 0.65546536 | V9: =+SUM(T9:U9) -> 1 | X9: =+X8/X7 -> #REF!
B10: Cost | C10: =+C7*C8 -> 1733750 | D10: =+D7*D8 -> 2533930 | E10: =+C10+D10 -> 4267680 | G10: Cost | H10: =+H7*H8 -> 1733750 | I10: =+I7*I8 -> 2533930 | J10: =+J7*J8 -> 1176465 | K10: =+SUM(H10:J10) -> 5444145 | M10: Cost | N10: =+N7*N8 -> 1662500 | O10: =+O7*O8 -> 2533930 | P10: =+P7*P8 -> 1306800 | Q10: =+SUM(N10:P10) -> 5503230 | S10: Cost | T10: =+T7*T8 -> 1733750 | U10: =+U8*U7 -> 3694208 | V10: =+SUM(T10:U10) -> 5427958
B11: Transportation | C11: 75000 | D11: 75000 | E11: =+C11+D11 -> 150000 | G11: Transportation | H11: 75000 | I11: 75000 | J11: 50000 | K11: =+SUM(H11:J11) -> 200000 | M11: Transportation | N11: 75000 | O11: 75000 | P11: 50000 | Q11: =+SUM(N11:P11) -> 200000 | S11: Transportation | T11: 50000 | U11: 100000 | V11: =+SUM(T11:U11) -> 150000
B12: HKB | C12: =+C9*H1 -> 51951.133 | D12: =+D9*H1 -> 68048.867 | E12: =+C12+D12 -> 120000 | G12: HKB | H12: =+$H$1*H9 -> 41204.139 | I12: =+$H$1*I9 -> 53971.778 | J12: =+$H$1*J9 -> 24824.083 | K12: =+SUM(H12:J12) -> 120000 | M12: HKB | N12: =+$H$1*N9 -> 39510.818 | O12: =+$H$1*O9 -> 53971.778 | P12: =+$H$1*P9 -> 24383.819 | Q12: =+SUM(N12:P12) -> 117866.42 | S12: HKB | T12: =+T9*$H$1 -> 41344.157 | U12: =+U9*$H$1 -> 78655.843 | V12: =+SUM(T12:U12) -> 120000
B13: Labour | C13: =+C9*L1 -> 12987.783 | D13: =+D9*N1 -> 17012.217 | E13: =+C13+D13 -> 30000 | G13: Labour | H13: =+$L$1*H9 -> 10301.035 | I13: =+$L$1*I9 -> 13492.944 | J13: =+$L$1*J9 -> 6206.0207 | K13: =+SUM(H13:J13) -> 30000 | M13: Labour | N13: =+$L$1*N9 -> 9877.7046 | O13: =+$L$1*O9 -> 13492.944 | P13: =+$L$1*P9 -> 6095.9548 | Q13: =+SUM(N13:P13) -> 29466.604 | S13: Labour | T13: =+T9*$L$1 -> 10336.039 | U13: =+U9*$L$1 -> 19663.961 | V13: =+SUM(T13:U13) -> 30000
B14: Other Exp | C14: =+C9*N1 -> 12987.783 | D14: =+D9*N1 -> 17012.217 | E14: =+C14+D14 -> 30000 | G14: Other Exp | H14: =+$N$1*H9 -> 10301.035 | I14: =+$N$1*I9 -> 13492.944 | J14: =+$N$1*J9 -> 6206.0207 | K14: =+SUM(H14:J14) -> 30000 | M14: Other Exp | N14: =+$N$1*N9 -> 9877.7046 | O14: =+$N$1*O9 -> 13492.944 | P14: =+$N$1*P9 -> 6095.9548 | Q14: =+SUM(N14:P14) -> 29466.604 | S14: Other Exp | T14: =+T9*$N$1 -> 10336.039 | U14: =+U9*$N$1 -> 19663.961 | V14: =+SUM(T14:U14) -> 30000
B15: Weight loss 6% | C15: =+C10*0.06 -> 104025 | D15: =+D10*0.06 -> 152035.8 | E15: =+C15+D15 -> 256060.8 | G15: Weight loss 6% | H15: =+(H7*0.06)*H8 -> 104025 | I15: =+(I7*0.06)*I8 -> 152035.8 | J15: =+(J7*0.06)*J8 -> 70587.9 | K15: =+SUM(H15:J15) -> 326648.7 | M15: Weight loss 6% | N15: =+(N7*0.06)*N8 -> 99750 | O15: =+(O7*0.06)*O8 -> 152035.8 | P15: 0 | Q15: =+SUM(N15:P15) -> 251785.8 | S15: Weight loss 6% | T15: =+(T7*0.06)*T8 -> 104025 | U15: =+(U7*0.06)*U8 -> 221652.48 | V15: =+SUM(T15:U15) -> 325677.48
B16: Toal Cost | C16: =+SUM(C10:C15) -> 1990701.7 | D16: =+SUM(D10:D15) -> 2863039.1 | E16: =+C16+D16 -> 4853740.8 | G16: Toal Cost | H16: =+SUM(H10:H15) -> 1974581.2 | I16: =+SUM(I10:I15) -> 2841923.5 | J16: =+SUM(J10:J15) -> 1334289 | K16: =+SUM(H16:J16) -> 6150793.7 | M16: Toal Cost | N16: =+SUM(N10:N15) -> 1896516.2 | O16: =+SUM(O10:O15) -> 2841923.5 | P16: =+SUM(P10:P15) -> 1393375.7 | Q16: =+SUM(N16:P16) -> 6131815.4 | S16: Toal Cost | T16: =+SUM(T10:T15) -> 1949791.2 | U16: =+SUM(U10:U15) -> 4133844.2 | V16: =+SUM(T16:U16) -> 6083635.5
B17: Rate @home | C17: =+C16/C7 -> 545.39773 | D17: =+D16/D7 -> 598.83688 | G17: Rate @home | H17: =+H16/H7 -> 540.98115 | I17: =+I16/I7 -> 594.4203 | J17: =+J16/J7 -> 606.77082 | M17: Rate @home | N17: =+N16/N7 -> 541.86178 | O17: =+O16/O7 -> 594.4203 | P17: =+P16/P5 -> 58057.322 | S17: Rate @home | T17: =+T16/T7 -> 534.18938 | U17: =+U16/U7 -> 595.31167
B18: Selling price | C18: 575 | D18: 600 | G18: Selling price | H18: 575 | I18: 600 | J18: 600 | M18: Selling price | N18: 575 | O18: 600 | P18: 62000 | S18: Selling price | T18: 575 | U18: 600
B19: Total Sale | C19: =+C18*C7 -> 2098750 | D19: =+D18*D7 -> 2868600 | E19: =+C19+D19 -> 4967350 | G19: Total Sale | H19: =+H18*H7 -> 2098750 | I19: =+I18*I7 -> 2868600 | J19: =+J18*J7 -> 1319400 | K19: =+SUM(H19:J19) -> 6286750 | M19: Total Sale | N19: =+N18*N7 -> 2012500 | O19: =+O18*O7 -> 2868600 | P19: =+P18*P5 -> 1488000 | Q19: =+SUM(N19:P19) -> 6369100 | S19: Total Sale | T19: =+T18*T7 -> 2098750 | U19: =+U18*U7 -> 4166400 | V19: =+SUM(T19:U19) -> 6265150
B20: Profit | C20: =+C19-C16 -> 108048.3 | D20: =+D19-D16 -> 5560.8991 | E20: =+C20+D20 -> 113609.2 | G20: Profit | H20: =+H19-H16 -> 124168.79 | I20: =+I19-I16 -> 26676.533 | J20: =+J19-J16 -> -14889.024 | K20: =+SUM(H20:J20) -> 135956.3 | M20: Profit | N20: =+N19-N16 -> 115983.77 | O20: =+O19-O16 -> 26676.533 | P20: =+P19-P16 -> 94624.271 | Q20: =+SUM(N20:P20) -> 237284.58 | S20: Profit | T20: =+T19-T16 -> 148958.76 | U20: =+U19-U16 -> 32555.756 | V20: =+SUM(T20:U20) -> 181514.52
B21: Jamil Bhai share | C21: =+C20*0.15 -> 16207.245 | D21: =+D20*0.15 -> 834.13486 | E21: =+C21+D21 -> 17041.38 | G21: Jamil Bhai share | H21: =+H20*0.15 -> 18625.319 | I21: =+I20*0.15 -> 4001.48 | J21: =+J20*0.15 -> -2233.3536 | K21: =+SUM(H21:J21) -> 20393.445 | M21: Jamil Bhai share | N21: =+N20*0.15 -> 17397.566 | O21: =+O20*0.15 -> 4001.48 | P21: =+P20*0.15 -> 14193.641 | Q21: =+SUM(N21:P21) -> 35592.686 | S21: Jamil Bhai share | T21: =+T20*0.15 -> 22343.815 | U21: =+U20*0.15 -> 4883.3633 | V21: =+SUM(T21:U21) -> 27227.178
B22: Nett Profit | C22: =+C20-C21 -> 91841.056 | D22: =+D20-D21 -> 4726.7642 | E22: =+C22+D22 -> 96567.82 | G22: Nett Profit | H22: =+H20-H21 -> 105543.47 | I22: =+I20-I21 -> 22675.053 | J22: =+J20-J21 -> -12655.671 | K22: =+SUM(H22:J22) -> 115562.86 | M22: Nett Profit | N22: =+N20-N21 -> 98586.206 | O22: =+O20-O21 -> 22675.053 | P22: =+P20-P21 -> 80430.63 | Q22: =+SUM(N22:P22) -> 201691.89 | S22: Nett Profit | T22: =+T20-T21 -> 126614.95 | U22: =+U20-U21 -> 27672.392 | V22: =+SUM(T22:U22) -> 154287.34
B25: Average | C25: =+C6*0.94 -> 68.62 | D25: =+D6*0.94 -> 66.74 | G25: Average | H25: =+H6*0.94 -> 68.62 | I25: =+I6*0.94 -> 68.62 | J25: =+J6*0.94 -> 69.56 | K25: =+K7*0.06 -> 637.8 | M25: Average | N25: =+N6*0.94 -> 65.8 | O25: =+O6*0.94 -> 68.62 | P25: =+P6*0.94 -> 84.6 | S25: Average | T25: =+T6*0.94 -> 68.62 | U25: =+U6*0.94 -> 69.56
B26: Cost per goat | C26: =+C16/C5 -> 39814.034 | D26: =+D16/D5 -> 42731.927 | G26: Cost per goat | H26: =+H16/H5 -> 39491.624 | I26: =+I16/I5 -> 42416.768 | J26: =+J16/J5 -> 46009.966 | M26: Cost per goat | N26: =+N16/N5 -> 37930.325 | O26: =+O16/O5 -> 42416.768 | P26: =+P16/P5 -> 58057.322 | S26: Cost per goat | T26: =+T16/T5 -> 38995.825 | U26: =+U16/U5 -> 43977.066
B27: Selling per goat | C27: 41000 | D27: 45000 | G27: Selling per goat | H27: 41000 | I27: 45000 | J27: 45000 | M27: Selling per goat | N27: 41000 | O27: 45000 | P27: 60000 | S27: Selling per goat | T27: 41000 | U27: 45000
B28: Total Sale | C28: =+C27*C5 -> 2050000 | D28: =+D27*D5 -> 3015000 | E28: =+C28+D28 -> 5065000 | G28: Total Sale | H28: =+H27*H5 -> 2050000 | I28: =+I27*I5 -> 3015000 | J28: =+J27*J5 -> 1305000 | K28: =+H28+I28+J28 -> 6370000 | M28: Total Sale | N28: =+N27*N5 -> 2050000 | O28: =+O27*O5 -> 3015000 | P28: =+P27*P5 -> 1440000 | Q28: =+N28+O28+P28 -> 6505000 | S28: Total Sale | T28: =+T27*T5 -> 2050000 | U28: =+U27*U5 -> 4230000 | V28: =+T28+U28 -> 6280000
C29: =+C27/C6 -> 561.64384 | D29: =+D27/D6 -> 633.80282 | E29: =+E28-E16 -> 211259.2 | H29: =+H27/H6 -> 561.64384 | I29: =+I27/I6 -> 616.43836 | J29: =+J27/J6 -> 608.10811 | K29: =+K28-K16 -> 219206.3 | N29: =+N27/N6 -> 585.71429 | O29: =+O27/O6 -> 616.43836 | P29: =+P27/P6 -> 666.66667 | Q29: =+Q28-Q16 -> 373184.58 | T29: =+T27/T6 -> 561.64384 | U29: =+U27/U6 -> 608.10811 | V29: =+V28-V16 -> 196364.52
C30: =+C27-C26 -> 1185.966 | D30: =+D27-D26 -> 2268.0731 | H30: =+H27-H26 -> 1508.3758 | I30: =+I27-I26 -> 2583.2318 | J30: =+J27-J26 -> -1009.9664 | N30: =+N27-N26 -> 3069.6754 | O30: =+O27-O26 -> 2583.2318 | P30: =+P27-P26 -> 1942.678 | T30: =+T27-T26 -> 2004.1753 | U30: =+U27-U26 -> 1022.9336
C31: =+C30*C5 -> 59298.301 | D31: =+D30*D5 -> 151960.9 | H31: =+H30*H5 -> 75418.791 | I31: =+I30*I5 -> 173076.53 | J31: =+J30*J5 -> -29289.024 | N31: =+N30*N5 -> 153483.77 | O31: =+O30*O5 -> 173076.53 | P31: =+P30*P5 -> 46624.271 | T31: =+T30*T5 -> 100208.76 | U31: =+U30*U5 -> 96155.756

Sheet Sojat Weight list
B1: Original Weight | C1: Actual Weight % | D1: Actual Weight | E1: Rate per kg | F1: Amount | G1: Weight Loss | H1: Weight loss cost | I1: Transportation | J1: HKB Lawn | K1: Other exp | L1: Cost per goat | M1: Rate per goat p/kg
B2: 46 | C2: 0.95 | D2: =+B2*C2 -> 43.7 | E2: 530 | F2: =+B2*E2 -> 24380 | G2: =+B2-D2 -> 2.3 | H2: =+E2*G2 -> 1219 | I2: =+($T$2*B2)/$B$70 -> 721.57617 | J2: =+(B2*$T$3)/$B$70 -> 654.69922 | K2: =+(B2*$T$6)/$B$70 -> 327.34961 | L2: =+SUM(F2+H2+I2+J2+K2) -> 27302.625 | M2: =+L2/B2 -> 593.53533 | N2: 625 | O2: =+D2*N2 -> 27312.5 | T2: 75000 | U2: 5000
B3: 57.7 | C3: 0.95 | D3: =+B3*C3 -> 54.815 | E3: 530 | F3: =+B3*E3 -> 30581 | G3: =+B3-D3 -> 2.885 | H3: =+E3*G3 -> 1529.05 | I3: =+($T$2*B3)/$B$70 -> 905.1075 | J3: =+(B3*$T$3)/$B$70 -> 821.22054 | K3: =+(B3*$T$6)/$B$70 -> 410.61027 | L3: =+SUM(F3+H3+I3+J3+K3) -> 34246.988 | M3: =+L3/B3 -> 593.53533 | N3: 625 | O3: =+D3*N3 -> 34259.375 | T3: 68048.867
B4: 58 | C4: 0.95 | D4: =+B4*C4 -> 55.1 | E4: 530 | F4: =+B4*E4 -> 30740 | G4: =+B4-D4 -> 2.9 | H4: =+E4*G4 -> 1537 | I4: =+($T$2*B4)/$B$70 -> 909.81344 | J4: =+(B4*$T$3)/$B$70 -> 825.49032 | K4: =+(B4*$T$6)/$B$70 -> 412.74516 | L4: =+SUM(F4+H4+I4+J4+K4) -> 34425.049 | M4: =+L4/B4 -> 593.53533 | N4: 625 | O4: =+D4*N4 -> 34437.5 | T4: 17012.217
B5: 58 | C5: 0.95 | D5: =+B5*C5 -> 55.1 | E5: 530 | F5: =+B5*E5 -> 30740 | G5: =+B5-D5 -> 2.9 | H5: =+E5*G5 -> 1537 | I5: =+($T$2*B5)/$B$70 -> 909.81344 | J5: =+(B5*$T$3)/$B$70 -> 825.49032 | K5: =+(B5*$T$6)/$B$70 -> 412.74516 | L5: =+SUM(F5+H5+I5+J5+K5) -> 34425.049 | M5: =+L5/B5 -> 593.53533 | N5: 625 | O5: =+D5*N5 -> 34437.5 | T5: 17012.217
B6: 58 | C6: 0.95 | D6: =+B6*C6 -> 55.1 | E6: 530 | F6: =+B6*E6 -> 30740 | G6: =+B6-D6 -> 2.9 | H6: =+E6*G6 -> 1537 | I6: =+($T$2*B6)/$B$70 -> 909.81344 | J6: =+(B6*$T$3)/$B$70 -> 825.49032 | K6: =+(B6*$T$6)/$B$70 -> 412.74516 | L6: =+SUM(F6+H6+I6+J6+K6) -> 34425.049 | M6: =+L6/B6 -> 593.53533 | N6: 625 | O6: =+D6*N6 -> 34437.5 | T6: =+T4+T5 -> 34024.434
B7: 59 | C7: 0.95 | D7: =+B7*C7 -> 56.05 | E7: 530 | F7: =+B7*E7 -> 31270 | G7: =+B7-D7 -> 2.95 | H7: =+E7*G7 -> 1563.5 | I7: =+($T$2*B7)/$B$70 -> 925.49987 | J7: =+(B7*$T$3)/$B$70 -> 839.72291 | K7: =+(B7*$T$6)/$B$70 -> 419.86145 | L7: =+SUM(F7+H7+I7+J7+K7) -> 35018.584 | M7: =+L7/B7 -> 593.53533 | N7: 625 | O7: =+D7*N7 -> 35031.25
B8: 60.5 | C8: 0.95 | D8: =+B8*C8 -> 57.475 | E8: 530 | F8: =+B8*E8 -> 32065 | G8: =+B8-D8 -> 3.025 | H8: =+E8*G8 -> 1603.25 | I8: =+($T$2*B8)/$B$70 -> 949.02953 | J8: =+(B8*$T$3)/$B$70 -> 861.0718 | K8: =+(B8*$T$6)/$B$70 -> 430.5359 | L8: =+SUM(F8+H8+I8+J8+K8) -> 35908.887 | M8: =+L8/B8 -> 593.53533 | N8: 625 | O8: =+D8*N8 -> 35921.875
B9: 60.5 | C9: 0.95 | D9: =+B9*C9 -> 57.475 | E9: 530 | F9: =+B9*E9 -> 32065 | G9: =+B9-D9 -> 3.025 | H9: =+E9*G9 -> 1603.25 | I9: =+($T$2*B9)/$B$70 -> 949.02953 | J9: =+(B9*$T$3)/$B$70 -> 861.0718 | K9: =+(B9*$T$6)/$B$70 -> 430.5359 | L9: =+SUM(F9+H9+I9+J9+K9) -> 35908.887 | M9: =+L9/B9 -> 593.53533 | N9: 625 | O9: =+D9*N9 -> 35921.875
B10: 60.5 | C10: 0.95 | D10: =+B10*C10 -> 57.475 | E10: 530 | F10: =+B10*E10 -> 32065 | G10: =+B10-D10 -> 3.025 | H10: =+E10*G10 -> 1603.25 | I10: =+($T$2*B10)/$B$70 -> 949.02953 | J10: =+(B10*$T$3)/$B$70 -> 861.0718 | K10: =+(B10*$T$6)/$B$70 -> 430.5359 | L10: =+SUM(F10+H10+I10+J10+K10) -> 35908.887 | M10: =+L10/B10 -> 593.53533 | N10: 625 | O10: =+D10*N10 -> 35921.875
B11: 61 | C11: 0.95 | D11: =+B11*C11 -> 57.95 | E11: 530 | F11: =+B11*E11 -> 32330 | G11: =+B11-D11 -> 3.05 | H11: =+E11*G11 -> 1616.5 | I11: =+($T$2*B11)/$B$70 -> 956.87275 | J11: =+(B11*$T$3)/$B$70 -> 868.18809 | K11: =+(B11*$T$6)/$B$70 -> 434.09405 | L11: =+SUM(F11+H11+I11+J11+K11) -> 36205.655 | M11: =+L11/B11 -> 593.53533 | N11: 625 | O11: =+D11*N11 -> 36218.75
B12: 61 | C12: 0.95 | D12: =+B12*C12 -> 57.95 | E12: 530 | F12: =+B12*E12 -> 32330 | G12: =+B12-D12 -> 3.05 | H12: =+E12*G12 -> 1616.5 | I12: =+($T$2*B12)/$B$70 -> 956.87275 | J12: =+(B12*$T$3)/$B$70 -> 868.18809 | K12: =+(B12*$T$6)/$B$70 -> 434.09405 | L12: =+SUM(F12+H12+I12+J12+K12) -> 36205.655 | M12: =+L12/B12 -> 593.53533 | N12: 625 | O12: =+D12*N12 -> 36218.75
B13: 62 | C13: 0.95 | D13: =+B13*C13 -> 58.9 | E13: 530 | F13: =+B13*E13 -> 32860 | G13: =+B13-D13 -> 3.1 | H13: =+E13*G13 -> 1643 | I13: =+($T$2*B13)/$B$70 -> 972.55919 | J13: =+(B13*$T$3)/$B$70 -> 882.42068 | K13: =+(B13*$T$6)/$B$70 -> 441.21034 | L13: =+SUM(F13+H13+I13+J13+K13) -> 36799.19 | M13: =+L13/B13 -> 593.53533 | N13: 625 | O13: =+D13*N13 -> 36812.5
B14: 63 | C14: 0.95 | D14: =+B14*C14 -> 59.85 | E14: 530 | F14: =+B14*E14 -> 33390 | G14: =+B14-D14 -> 3.15 | H14: =+E14*G14 -> 1669.5 | I14: =+($T$2*B14)/$B$70 -> 988.24563 | J14: =+(B14*$T$3)/$B$70 -> 896.65327 | K14: =+(B14*$T$6)/$B$70 -> 448.32664 | L14: =+SUM(F14+H14+I14+J14+K14) -> 37392.726 | M14: =+L14/B14 -> 593.53533 | N14: 625 | O14: =+D14*N14 -> 37406.25
B15: 63 | C15: 0.95 | D15: =+B15*C15 -> 59.85 | E15: 530 | F15: =+B15*E15 -> 33390 | G15: =+B15-D15 -> 3.15 | H15: =+E15*G15 -> 1669.5 | I15: =+($T$2*B15)/$B$70 -> 988.24563 | J15: =+(B15*$T$3)/$B$70 -> 896.65327 | K15: =+(B15*$T$6)/$B$70 -> 448.32664 | L15: =+SUM(F15+H15+I15+J15+K15) -> 37392.726 | M15: =+L15/B15 -> 593.53533 | N15: 625 | O15: =+D15*N15 -> 37406.25
B16: 63 | C16: 0.95 | D16: =+B16*C16 -> 59.85 | E16: 530 | F16: =+B16*E16 -> 33390 | G16: =+B16-D16 -> 3.15 | H16: =+E16*G16 -> 1669.5 | I16: =+($T$2*B16)/$B$70 -> 988.24563 | J16: =+(B16*$T$3)/$B$70 -> 896.65327 | K16: =+(B16*$T$6)/$B$70 -> 448.32664 | L16: =+SUM(F16+H16+I16+J16+K16) -> 37392.726 | M16: =+L16/B16 -> 593.53533 | N16: 625 | O16: =+D16*N16 -> 37406.25
B17: 65 | C17: 0.95 | D17: =+B17*C17 -> 61.75 | E17: 530 | F17: =+B17*E17 -> 34450 | G17: =+B17-D17 -> 3.25 | H17: =+E17*G17 -> 1722.5 | I17: =+($T$2*B17)/$B$70 -> 1019.6185 | J17: =+(B17*$T$3)/$B$70 -> 925.11846 | K17: =+(B17*$T$6)/$B$70 -> 462.55923 | L17: =+SUM(F17+H17+I17+J17+K17) -> 38579.796 | M17: =+L17/B17 -> 593.53533 | N17: 625 | O17: =+D17*N17 -> 38593.75
B18: 65 | C18: 0.95 | D18: =+B18*C18 -> 61.75 | E18: 530 | F18: =+B18*E18 -> 34450 | G18: =+B18-D18 -> 3.25 | H18: =+E18*G18 -> 1722.5 | I18: =+($T$2*B18)/$B$70 -> 1019.6185 | J18: =+(B18*$T$3)/$B$70 -> 925.11846 | K18: =+(B18*$T$6)/$B$70 -> 462.55923 | L18: =+SUM(F18+H18+I18+J18+K18) -> 38579.796 | M18: =+L18/B18 -> 593.53533 | N18: 625 | O18: =+D18*N18 -> 38593.75
... B68: 102 | C68: 0.95 | D68: =+B68*C68 -> 96.9 | E68: 530 | F68: =+B68*E68 -> 54060 | G68: =+B68-D68 -> 5.1 | H68: =+E68*G68 -> 2703 | I68: =+($T$2*B68)/$B$70 -> 1600.0167 | J68: =+(B68*$T$3)/$B$70 -> 1451.7243 | K68: =+(B68*$T$6)/$B$70 -> 725.86217 | L68: =+SUM(F68+H68+I68+J68+K68) -> 60540.603 | M68: =+L68/B68 -> 593.53533 | N68: 675 | O68: =+D68*N68 -> 65407.5
B70: =+SUM(B2:B68) -> 4781.2 | D70: =+SUM(D2:D68) -> 4542.14 | F70: =+SUM(F2:F68) -> 2534036 | G70: =+SUM(G2:G68) -> 239.06 | H70: =+SUM(H2:H68) -> 126701.8 | I70: =+SUM(I2:I68) -> 75000 | J70: =+SUM(J2:J68) -> 68048.867 | K70: =+SUM(K2:K68) -> 34024.434 | L70: =+SUM(L2:L68) -> 2837811.1 | O70: =+SUM(O2:O68) -> 2898086.6
B71: 530
B72: =+B70*B71 -> 2534036 | O72: =+O70-B74 -> 184050.62
B73: 180000
B74: =+B72+B73 -> 2714036
B75: =+B74/67 -> 40508

Sheet option1
A1: Transportation cost | B1: 82000 | C1: Rent | D1: 90000 | E1: Palai days | F1: 46126 | G1: 46162 | H1: =+G1-F1 -> 36
A2: Total goat | B2: 90 | C2: Total goat | D2: 90 | E2: Palai per day | F2: 90 | G2: Palai per goat | H2: =+F2*H1 -> 3240
A3: Per goat | B3: =+B1/B2 -> 911.11111 | C3: Per goat | D3: =+D1/D2 -> 1000 | E3: Total Goat | F3: 90 | G3: Total Palai 90 goats | H3: =+H1*F2*F3 -> 291600
A5: Sr No | B5: Date of Sale | C5: Name of the Buyer | D5: Weight | E5: Goat per Kg | F5: Goat Cost | G5: Transportation | H5: Rent | I5: Palai | J5: Total Cost | K5: Cost per kg | L5: Rate | M5: Amount | N5: Palai | O5: Total Amount | P5: Profit | Q5: Selling Rate | R5: Difference | S5: Profit
A6: 1 | B6: 46125 | C6: Guddu Bhai | D6: 83 | E6: 475 | F6: =+D6*E6 -> 39425 | G6: =+$B$3 -> 911.11111 | H6: =+$D$3 -> 1000 | I6: =+$H$2 -> 3240 | J6: =+SUM(F6:I6) -> 44576.111 | K6: =+J6/D6 -> 537.06158 | L6: 600 | M6: =+D6*L6 -> 49800 | N6: 4000 | O6: =+M6+N6 -> 53800 | P6: =+O6-J6 -> 9223.8889 | Q6: =+O6/D6 -> 648.19277 | R6: =+Q6-K6 -> 111.13119 | S6: =+R6*D6 -> 9223.8889
A7: 2 | B7: 46126 | C7: Azam Kharghar | D7: 136 | E7: 475 | F7: =+D7*E7 -> 64600 | G7: =+$B$3 -> 911.11111 | H7: =+$D$3 -> 1000 | I7: =+$H$2 -> 3240 | J7: =+F7+SUM(G7:I7)+SUM(G8:I8) -> 74902.222 | K7: =+J7/D7 -> 550.75163 | L7: 600 | M7: =+D7*L7 -> 81600 | N7: 4000 | O7: =+M7+N7+N8 -> 89600 | P7: =+O7-J7 -> 14697.778 | Q7: =+O7/D7 -> 658.82353 | R7: =+Q7-K7 -> 108.0719 | S7: =+R7*D7 -> 14697.778
A8: 3 | B8: 46126 | C8: Azam Kharghar | E8: 475 | G8: =+$B$3 -> 911.11111 | H8: =+$D$3 -> 1000 | I8: =+$H$2 -> 3240 | N8: 4000
A9: 4 | B9: 46130 | C9: Salman Vikhroli | D9: 132 | E9: 475 | F9: =+D9*E9 -> 62700 | G9: =+$B$3 -> 911.11111 | H9: =+$D$3 -> 1000 | I9: =+$H$2 -> 3240 | J9: =+F9+SUM(G9:I9)+SUM(G10:I10) -> 73002.222 | K9: =+J9/D9 -> 553.04714 | L9: 600 | M9: =+D9*L9 -> 79200 | N9: 3000 | O9: =+M9+N9+N10 -> 85200 | P9: =+O9-J9 -> 12197.778 | Q9: =+O9/D9 -> 645.45455 | R9: =+Q9-K9 -> 92.407407 | S9: =+R9*D9 -> 12197.778
A10: 5 | B10: 46130 | C10: Salman Vikhroli | E10: 475 | G10: =+$B$3 -> 911.11111 | H10: =+$D$3 -> 1000 | I10: =+$H$2 -> 3240 | N10: 3000
A11: 6 | B11: 46130 | C11: Iqbal Bhai Khar | D11: 358 | E11: 475 | F11: =+D11*E11 -> 170050 | G11: =+$B$3 -> 911.11111 | H11: =+$D$3 -> 1000 | I11: =+$H$2 -> 3240 | J11: =+F11+SUM(G11:G15)+SUM(H11:H15)+SUM(I11:I15) -> 195805.56 | K11: =+J11/D11 -> 546.94289 | L11: 600 | M11: =+D11*L11 -> 214800 | N11: 3000 | O11: =+M11+SUM(N11:N15) -> 229800 | P11: =+O11-J11 -> 33994.444 | Q11: =+O11/D11 -> 641.89944 | R11: =+Q11-K11 -> 94.956549 | S11: =+R11*D11 -> 33994.444
A12: 7 | B12: 46130 | C12: Iqbal Bhai Khar | E12: 475 | G12: =+$B$3 -> 911.11111 | H12: =+$D$3 -> 1000 | I12: =+$H$2 -> 3240 | N12: 3000
A13: 8 | B13: 46130 | C13: Iqbal Bhai Khar | E13: 475 | G13: =+$B$3 -> 911.11111 | H13: =+$D$3 -> 1000 | I13: =+$H$2 -> 3240 | N13: 3000
A14: 9 | B14: 46130 | C14: Iqbal Bhai Khar | E14: 475 | G14: =+$B$3 -> 911.11111 | H14: =+$D$3 -> 1000 | I14: =+$H$2 -> 3240 | N14: 3000
A15: 10 | B15: 46130 | C15: Iqbal Bhai Khar | E15: 475 | G15: =+$B$3 -> 911.11111 | H15: =+$D$3 -> 1000 | I15: =+$H$2 -> 3240 | N15: 3000
A16: 11 | B16: 46130 | C16: Sajid Bhai Jogeshwari | D16: 144 | E16: 475 | F16: =+D16*E16 -> 68400 | G16: =+$B$3 -> 911.11111 | H16: =+$D$3 -> 1000 | I16: =+$H$2 -> 3240 | J16: =+F16+SUM(G16:I16)+SUM(G17:I17) -> 78702.222 | K16: =+J16/D16 -> 546.54321 | L16: 600 | M16: =+D16*L16 -> 86400 | N16: 3300 | O16: =+M16+N16+N17 -> 93000 | P16: =+O16-J16 -> 14297.778 | Q16: =+O16/D16 -> 645.83333 | R16: =+Q16-K16 -> 99.290123 | S16: =+R16*D16 -> 14297.778
A17: 12 | B17: 46130 | C17: Sajid Bhai Jogeshwari | E17: 475 | G17: =+$B$3 -> 911.11111 | H17: =+$D$3 -> 1000 | I17: =+$H$2 -> 3240 | N17: 3300
A18: 13 | B18: 46130 | C18: Kashaf Bhai c/o Sarfaraz bhai | D18: 128 | E18: 475 | F18: =+D18*E18 -> 60800 | G18: =+$B$3 -> 911.11111 | H18: =+$D$3 -> 1000 | I18: =+$H$2 -> 3240 | J18: =+F18+SUM(G18:I18)+SUM(G19:I19) -> 71102.222 | K18: =+J18/D18 -> 555.48611 | L18: 600 | M18: =+D18*L18 -> 76800 | N18: 3300 | O18: =+M18+N18+N19 -> 83400 | P18: =+O18-J18 -> 12297.778 | Q18: =+O18/D18 -> 651.5625 | R18: =+Q18-K18 -> 96.076389 | S18: =+R18*D18 -> 12297.778
A19: 14 | B19: 46130 | C19: Kashaf Bhai c/o Sarfaraz bhai | E19: 475 | G19: =+$B$3 -> 911.11111 | H19: =+$D$3 -> 1000 | I19: =+$H$2 -> 3240 | N19: 3300
A20: 15 | B20: 46131 | C20: Mohd Faizaan | D20: 123 | E20: 475 | F20: =+D20*E20 -> 58425 | G20: =+$B$3 -> 911.11111 | H20: =+$D$3 -> 1000 | I20: =+$H$2 -> 3240 | J20: =+F20+SUM(G20:I20)+SUM(G21:I21) -> 68727.222 | K20: =+J20/D20 -> 558.7579 | L20: 626.017 | M20: =+D20*L20 -> 77000.091 | N20: 3500 | O20: =+SUM(M20+N20+N21) -> 84000.091 | P20: =+O20-J20 -> 15272.869 | Q20: =+O20/D20 -> 682.92757 | R20: =+Q20-K20 -> 124.16966 | S20: =+R20*D20 -> 15272.869
A21: 16 | B21: 46131 | C21: Mohd Faizaan | E21: 475 | G21: =+$B$3 -> 911.11111 | H21: =+$D$3 -> 1000 | I21: =+$H$2 -> 3240 | M21: =+D21*L21 -> 0 | N21: 3500
A22: 17 | B22: 46131 | C22: Salman Akhlak | D22: 115 | E22: 475 | F22: =+D22*E22 -> 54625 | G22: =+$B$3 -> 911.11111 | H22: =+$D$3 -> 1000 | I22: =+$H$2 -> 3240 | J22: =+SUM(F22+SUM(G22:I22)+SUM(G23:I23)) -> 64927.222 | K22: =+J22/D22 -> 564.58454 | L22: 600 | M22: =+D22*L22 -> 69000 | N22: 3000 | O22: =+M22+N22+N23 -> 75000 | P22: =+O22-J22 -> 10072.778 | Q22: =+O22/D22 -> 652.17391 | R22: =+Q22-K22 -> 87.589372 | S22: =+R22*D22 -> 10072.778
A23: 18 | B23: 46131 | C23: Salman Akhlak | E23: 475 | G23: =+$B$3 -> 911.11111 | H23: =+$D$3 -> 1000 | I23: =+$H$2 -> 3240 | N23: 3000
A24: 19 | B24: 46131 | C24: Shahid Shaikh Kurla | D24: 136 | E24: 475 | F24: =+D24*E24 -> 64600 | G24: =+$B$3 -> 911.11111 | H24: =+$D$3 -> 1000 | I24: =+$H$2 -> 3240 | J24: =+F24+SUM(G24:I24)+SUM(G25:I25) -> 74902.222 | K24: =+J24/D24 -> 550.75163 | L24: 600 | M24: =+D24*L24 -> 81600 | N24: 3400 | O24: =+M24+N24+N25 -> 88400 | P24: =+O24-J24 -> 13497.778 | Q24: =+O24/D24 -> 650 | R24: =+Q24-K24 -> 99.248366 | S24: =+R24*D24 -> 13497.778
A25: 20 | B25: 46131 | C25: Shahid Shaikh Kurla | E25: 475 | G25: =+$B$3 -> 911.11111 | H25: =+$D$3 -> 1000 | I25: =+$H$2 -> 3240 | N25: 3400
A26: 21 | B26: 46131 | C26: Saif Bhai Kurla | D26: 374 | E26: 475 | F26: =+D26*E26 -> 177650 | G26: =+$B$3 -> 911.11111 | H26: =+$D$3 -> 1000 | I26: =+$H$2 -> 3240 | J26: =+SUM(F26+SUM(G26:G31)+SUM(H26:H31)+SUM(I26:I31)) -> 208556.67 | K26: =+J26/D26 -> 557.63815 | L26: 600 | M26: =+D26*L26 -> 224400 | N26: 3000 | O26: =+M26+SUM(N26:N31) -> 242400 | P26: =+O26-J26 -> 33843.333 | Q26: =+O26/D26 -> 648.12834 | R26: =+Q26-K26 -> 90.490196 | S26: =+R26*D26 -> 33843.333
A27: 22 | B27: 46131 | C27: Saif Bhai Kurla | E27: 475 | G27: =+$B$3 -> 911.11111 | H27: =+$D$3 -> 1000 | I27: =+$H$2 -> 3240 | N27: 3000
A28: 23 | B28: 46131 | C28: Saif Bhai Kurla | E28: 475 | G28: =+$B$3 -> 911.11111 | H28: =+$D$3 -> 1000 | I28: =+$H$2 -> 3240 | N28: 3000
A29: 24 | B29: 46131 | C29: Saif Bhai Kurla | E29: 475 | G29: =+$B$3 -> 911.11111 | H29: =+$D$3 -> 1000 | I29: =+$H$2 -> 3240 | N29: 3000
A30: 25 | B30: 46131 | C30: Saif Bhai Kurla | E30: 475 | G30: =+$B$3 -> 911.11111 | H30: =+$D$3 -> 1000 | I30: =+$H$2 -> 3240 | N30: 3000
A31: 26 | B31: 46131 | C31: Saif Bhai Kurla | E31: 475 | G31: =+$B$3 -> 911.11111 | H31: =+$D$3 -> 1000 | I31: =+$H$2 -> 3240 | N31: 3000
A32: 27 | B32: 46131 | C32: Imtiyaz Bhai sakinaka | D32: 88 | E32: 475 | F32: =+D32*E32 -> 41800 | G32: =+$B$3 -> 911.11111 | H32: =+$D$3 -> 1000 | I32: =+$H$2 -> 3240 | J32: =+SUM(F32:I32) -> 46951.111 | K32: =+J32/D32 -> 533.53535 | L32: 625 | M32: =+L32*D32 -> 55000 | N32: 3500 | O32: =+M32+N32 -> 58500 | P32: =+O32-J32 -> 11548.889 | Q32: =+O32/D32 -> 664.77273 | R32: =+Q32-K32 -> 131.23737 | S32: =+R32*D32 -> 11548.889
A33: 28 | B33: 46131 | C33: Faisal Sayyed | D33: 236 | E33: 475 | F33: =+D33*E33 -> 112100 | G33: =+$B$3 -> 911.11111 | H33: =+$D$3 -> 1000 | I33: =+$H$2 -> 3240 | J33: =+F33+SUM(G33:G36)+SUM(H33:H36)+SUM(I33:I36) -> 132704.44 | K33: =+J33/D33 -> 562.30697 | L33: 600 | M33: =+D33*L33 -> 141600 | N33: 3000 | O33: =+M33+SUM(N33:N36) -> 153600 | P33: =+O33-J33 -> 20895.556 | Q33: =+O33/D33 -> 650.84746 | R33: =+Q33-K33 -> 88.54049 | S33: =+R33*D33 -> 20895.556
A34: 29 | B34: 46131 | C34: Faisal Sayyed | E34: 475 | G34: =+$B$3 -> 911.11111 | H34: =+$D$3 -> 1000 | I34: =+$H$2 -> 3240 | N34: 3000
A35: 30 | B35: 46131 | C35: Faisal Sayyed | E35: 475 | G35: =+$B$3 -> 911.11111 | H35: =+$D$3 -> 1000 | I35: =+$H$2 -> 3240 | N35: 3000
A36: 31 | B36: 46131 | C36: Faisal Sayyed | E36: 475 | G36: =+$B$3 -> 911.11111 | H36: =+$D$3 -> 1000 | I36: =+$H$2 -> 3240 | N36: 3000
A37: 32 | B37: 46131 | C37: Nadeem bhai c/o Zain | D37: 118 | E37: 475 | F37: =+D37*E37 -> 56050 | G37: =+$B$3 -> 911.11111 | H37: =+$D$3 -> 1000 | I37: =+$H$2 -> 3240 | J37: =+F37+SUM(G37:I37)+SUM(G38:I38) -> 66352.222 | K37: =+J37/D37 -> 562.30697 | L37: 610 | M37: =+D37*L37 -> 71980 | N37: 3000 | O37: =+M37+N37+N38 -> 77980 | P37: =+O37-J37 -> 11627.778 | Q37: =+O37/D37 -> 660.84746 | R37: =+Q37-K37 -> 98.54049 | S37: =+R37*D37 -> 11627.778
A38: 33 | B38: 46131 | C38: Nadeem bhai c/o Zain | E38: 475 | G38: =+$B$3 -> 911.11111 | H38: =+$D$3 -> 1000 | I38: =+$H$2 -> 3240 | N38: 3000
A39: 34 | B39: 46134 | C39: Aushan Geswat | D39: 226 | E39: 475 | F39: =+D39*E39 -> 107350 | G39: =+$B$3 -> 911.11111 | H39: =+$D$3 -> 1000 | I39: =+$H$2 -> 3240 | J39: =+F39+SUM(G39:I39)+SUM(G40:I40)+SUM(G41:I41) -> 122803.33 | K39: =+J39/D39 -> 543.37758 | L39: 600 | M39: =+L39*D39 -> 135600 | N39: 3000 | O39: =+M39+SUM(N39:N41) -> 144600 | P39: =+O39-J39 -> 21796.667 | Q39: =+O39/D39 -> 639.82301 | R39: =+Q39-K39 -> 96.445428 | S39: =+R39*D39 -> 21796.667
A40: 35 | B40: 46134 | C40: Aushan Geswat | E40: 475 | G40: =+$B$3 -> 911.11111 | H40: =+$D$3 -> 1000 | I40: =+$H$2 -> 3240 | N40: 3000
A41: 36 | B41: 46134 | C41: Aushan Geswat | E41: 475 | G41: =+$B$3 -> 911.11111 | H41: =+$D$3 -> 1000 | I41: =+$H$2 -> 3240 | N41: 3000
...
